[2024-03-30T17:44:42.182+0000] {taskinstance.py:1979} INFO - Dependencies all met for dep_context=non-requeueable deps ti=<TaskInstance: study_case_etl_all_pipeline.bash_task_2 manual__2024-03-30T17:44:14.882021+00:00 [queued]>
[2024-03-30T17:44:42.190+0000] {taskinstance.py:1979} INFO - Dependencies all met for dep_context=requeueable deps ti=<TaskInstance: study_case_etl_all_pipeline.bash_task_2 manual__2024-03-30T17:44:14.882021+00:00 [queued]>
[2024-03-30T17:44:42.191+0000] {taskinstance.py:2193} INFO - Starting attempt 1 of 2
[2024-03-30T17:44:42.200+0000] {taskinstance.py:2214} INFO - Executing <Task(BashOperator): bash_task_2> on 2024-03-30 17:44:14.882021+00:00
[2024-03-30T17:44:42.205+0000] {standard_task_runner.py:60} INFO - Started process 561 to run task
[2024-03-30T17:44:42.208+0000] {standard_task_runner.py:87} INFO - Running: ['***', 'tasks', 'run', 'study_case_etl_all_pipeline', 'bash_task_2', 'manual__2024-03-30T17:44:14.882021+00:00', '--job-id', '138', '--raw', '--subdir', 'DAGS_FOLDER/running_dbt_core/study_case_etl_all_pipeline.py', '--cfg-path', '/tmp/tmpnnkuaqri']
[2024-03-30T17:44:42.212+0000] {standard_task_runner.py:88} INFO - Job 138: Subtask bash_task_2
[2024-03-30T17:44:42.247+0000] {task_command.py:423} INFO - Running <TaskInstance: study_case_etl_all_pipeline.bash_task_2 manual__2024-03-30T17:44:14.882021+00:00 [running]> on host f5156ab87ac1
[2024-03-30T17:44:42.307+0000] {taskinstance.py:2510} INFO - Exporting env vars: AIRFLOW_CTX_DAG_OWNER='Agus mahari' AIRFLOW_CTX_DAG_ID='study_case_etl_all_pipeline' AIRFLOW_CTX_TASK_ID='bash_task_2' AIRFLOW_CTX_EXECUTION_DATE='2024-03-30T17:44:14.882021+00:00' AIRFLOW_CTX_TRY_NUMBER='1' AIRFLOW_CTX_DAG_RUN_ID='manual__2024-03-30T17:44:14.882021+00:00'
[2024-03-30T17:44:42.310+0000] {subprocess.py:63} INFO - Tmp dir root location: /tmp
[2024-03-30T17:44:42.310+0000] {subprocess.py:75} INFO - Running command: ['/usr/bin/bash', '-c', 'cd /opt/***/dbt/credit_card_dwh && dbt run --profiles-dir .']
[2024-03-30T17:44:42.319+0000] {subprocess.py:86} INFO - Output:
[2024-03-30T17:44:44.632+0000] {subprocess.py:93} INFO - [0m17:44:44  Running with dbt=1.7.11
[2024-03-30T17:44:45.582+0000] {subprocess.py:93} INFO - [0m17:44:45  Registered adapter: bigquery=1.7.7
[2024-03-30T17:44:46.157+0000] {subprocess.py:93} INFO - [0m17:44:46  Found 1 model, 2 tests, 1 source, 0 exposures, 0 metrics, 907 macros, 0 groups, 0 semantic models
[2024-03-30T17:44:46.160+0000] {subprocess.py:93} INFO - [0m17:44:46
[2024-03-30T17:44:47.933+0000] {subprocess.py:93} INFO - [0m17:44:47  Concurrency: 4 threads (target='dev')
[2024-03-30T17:44:47.934+0000] {subprocess.py:93} INFO - [0m17:44:47
[2024-03-30T17:44:47.951+0000] {subprocess.py:93} INFO - [0m17:44:47  1 of 1 START sql incremental model final_project.stg__credit_card .............. [RUN]
[2024-03-30T17:44:49.595+0000] {subprocess.py:93} INFO - [0m17:44:49  1 of 1 ERROR creating sql incremental model final_project.stg__credit_card ..... [[31mERROR[0m in 1.64s]
[2024-03-30T17:44:49.605+0000] {subprocess.py:93} INFO - [0m17:44:49
[2024-03-30T17:44:49.607+0000] {subprocess.py:93} INFO - [0m17:44:49  Finished running 1 incremental model in 0 hours 0 minutes and 3.44 seconds (3.44s).
[2024-03-30T17:44:49.690+0000] {subprocess.py:93} INFO - [0m17:44:49
[2024-03-30T17:44:49.691+0000] {subprocess.py:93} INFO - [0m17:44:49  [31mCompleted with 1 error and 0 warnings:[0m
[2024-03-30T17:44:49.692+0000] {subprocess.py:93} INFO - [0m17:44:49
[2024-03-30T17:44:49.693+0000] {subprocess.py:93} INFO - [0m17:44:49    Runtime Error in model stg__credit_card (models/staging/stg__credit_card.sql)
[2024-03-30T17:44:49.694+0000] {subprocess.py:93} INFO -   404 Not found: Dataset forward-entity-411314:agusmahari_data_lake was not found in location US; reason: notFound, message: Not found: Dataset forward-entity-411314:agusmahari_data_lake was not found in location US
[2024-03-30T17:44:49.695+0000] {subprocess.py:93} INFO - 
[2024-03-30T17:44:49.697+0000] {subprocess.py:93} INFO -   Location: US
[2024-03-30T17:44:49.698+0000] {subprocess.py:93} INFO -   Job ID: 9d1e5cc6-57a5-4cc7-8f58-290770e09991
[2024-03-30T17:44:49.699+0000] {subprocess.py:93} INFO - 
[2024-03-30T17:44:49.700+0000] {subprocess.py:93} INFO - [0m17:44:49
[2024-03-30T17:44:49.703+0000] {subprocess.py:93} INFO - [0m17:44:49  Done. PASS=0 WARN=0 ERROR=1 SKIP=0 TOTAL=1
[2024-03-30T17:44:57.909+0000] {subprocess.py:97} INFO - Command exited with return code 1
[2024-03-30T17:44:57.919+0000] {taskinstance.py:2728} ERROR - Task failed with exception
Traceback (most recent call last):
  File "/home/airflow/.local/lib/python3.8/site-packages/airflow/models/taskinstance.py", line 444, in _execute_task
    result = _execute_callable(context=context, **execute_callable_kwargs)
  File "/home/airflow/.local/lib/python3.8/site-packages/airflow/models/taskinstance.py", line 414, in _execute_callable
    return execute_callable(context=context, **execute_callable_kwargs)
  File "/home/airflow/.local/lib/python3.8/site-packages/airflow/operators/bash.py", line 212, in execute
    raise AirflowException(
airflow.exceptions.AirflowException: Bash command failed. The command returned a non-zero exit code 1.
[2024-03-30T17:44:57.923+0000] {taskinstance.py:1149} INFO - Marking task as UP_FOR_RETRY. dag_id=study_case_etl_all_pipeline, task_id=bash_task_2, execution_date=20240330T174414, start_date=20240330T174442, end_date=20240330T174457
[2024-03-30T17:44:57.938+0000] {standard_task_runner.py:107} ERROR - Failed to execute job 138 for task bash_task_2 (Bash command failed. The command returned a non-zero exit code 1.; 561)
[2024-03-30T17:44:57.968+0000] {local_task_job_runner.py:234} INFO - Task exited with return code 1
[2024-03-30T17:44:57.985+0000] {taskinstance.py:3309} INFO - 0 downstream tasks scheduled from follow-on schedule check
