[2024-03-30T22:29:26.803+0000] {taskinstance.py:1979} INFO - Dependencies all met for dep_context=non-requeueable deps ti=<TaskInstance: study_case_etl_all_pipeline.bash_task_2 manual__2024-03-30T22:29:05.159199+00:00 [queued]>
[2024-03-30T22:29:26.811+0000] {taskinstance.py:1979} INFO - Dependencies all met for dep_context=requeueable deps ti=<TaskInstance: study_case_etl_all_pipeline.bash_task_2 manual__2024-03-30T22:29:05.159199+00:00 [queued]>
[2024-03-30T22:29:26.811+0000] {taskinstance.py:2193} INFO - Starting attempt 1 of 2
[2024-03-30T22:29:26.822+0000] {taskinstance.py:2214} INFO - Executing <Task(BashOperator): bash_task_2> on 2024-03-30 22:29:05.159199+00:00
[2024-03-30T22:29:26.827+0000] {standard_task_runner.py:60} INFO - Started process 5368 to run task
[2024-03-30T22:29:26.830+0000] {standard_task_runner.py:87} INFO - Running: ['***', 'tasks', 'run', 'study_case_etl_all_pipeline', 'bash_task_2', 'manual__2024-03-30T22:29:05.159199+00:00', '--job-id', '204', '--raw', '--subdir', 'DAGS_FOLDER/running_dbt_core/study_case_etl_all_pipeline.py', '--cfg-path', '/tmp/tmpbsq8kju1']
[2024-03-30T22:29:26.834+0000] {standard_task_runner.py:88} INFO - Job 204: Subtask bash_task_2
[2024-03-30T22:29:26.869+0000] {task_command.py:423} INFO - Running <TaskInstance: study_case_etl_all_pipeline.bash_task_2 manual__2024-03-30T22:29:05.159199+00:00 [running]> on host f5156ab87ac1
[2024-03-30T22:29:26.934+0000] {taskinstance.py:2510} INFO - Exporting env vars: AIRFLOW_CTX_DAG_OWNER='Agus mahari' AIRFLOW_CTX_DAG_ID='study_case_etl_all_pipeline' AIRFLOW_CTX_TASK_ID='bash_task_2' AIRFLOW_CTX_EXECUTION_DATE='2024-03-30T22:29:05.159199+00:00' AIRFLOW_CTX_TRY_NUMBER='1' AIRFLOW_CTX_DAG_RUN_ID='manual__2024-03-30T22:29:05.159199+00:00'
[2024-03-30T22:29:26.936+0000] {subprocess.py:63} INFO - Tmp dir root location: /tmp
[2024-03-30T22:29:26.937+0000] {subprocess.py:75} INFO - Running command: ['/usr/bin/bash', '-c', 'cd /opt/***/dbt/credit_card_dwh && dbt run --profiles-dir .']
[2024-03-30T22:29:26.947+0000] {subprocess.py:86} INFO - Output:
[2024-03-30T22:29:29.378+0000] {subprocess.py:93} INFO - [0m22:29:29  Running with dbt=1.7.11
[2024-03-30T22:29:30.330+0000] {subprocess.py:93} INFO - [0m22:29:30  Registered adapter: bigquery=1.7.7
[2024-03-30T22:29:30.491+0000] {subprocess.py:93} INFO - [0m22:29:30  Found 1 model, 2 tests, 1 source, 0 exposures, 0 metrics, 907 macros, 0 groups, 0 semantic models
[2024-03-30T22:29:30.495+0000] {subprocess.py:93} INFO - [0m22:29:30
[2024-03-30T22:29:31.700+0000] {subprocess.py:93} INFO - [0m22:29:31  Concurrency: 4 threads (target='dev')
[2024-03-30T22:29:31.701+0000] {subprocess.py:93} INFO - [0m22:29:31
[2024-03-30T22:29:31.713+0000] {subprocess.py:93} INFO - [0m22:29:31  1 of 1 START sql incremental model test_location.stg__credit_card .............. [RUN]
[2024-03-30T22:29:35.298+0000] {subprocess.py:93} INFO - [0m22:29:35  BigQuery adapter: https://console.cloud.google.com/bigquery?project=forward-entity-411314&j=bq:US:eb9f7476-57b0-4ee6-9d7c-e7fadcf40baa&page=queryresults
[2024-03-30T22:29:35.310+0000] {subprocess.py:93} INFO - [0m22:29:35  1 of 1 ERROR creating sql incremental model test_location.stg__credit_card ..... [[31mERROR[0m in 3.59s]
[2024-03-30T22:29:35.319+0000] {subprocess.py:93} INFO - [0m22:29:35
[2024-03-30T22:29:35.321+0000] {subprocess.py:93} INFO - [0m22:29:35  Finished running 1 incremental model in 0 hours 0 minutes and 4.82 seconds (4.82s).
[2024-03-30T22:29:35.341+0000] {subprocess.py:93} INFO - [0m22:29:35
[2024-03-30T22:29:35.342+0000] {subprocess.py:93} INFO - [0m22:29:35  [31mCompleted with 1 error and 0 warnings:[0m
[2024-03-30T22:29:35.343+0000] {subprocess.py:93} INFO - [0m22:29:35
[2024-03-30T22:29:35.345+0000] {subprocess.py:93} INFO - [0m22:29:35    Database Error in model stg__credit_card (models/staging/stg__credit_card.sql)
[2024-03-30T22:29:35.345+0000] {subprocess.py:93} INFO -   Cannot read and write in different locations: source: asia-southeast2, destination: US
[2024-03-30T22:29:35.346+0000] {subprocess.py:93} INFO -   compiled Code at target/run/credit_card_dwh/models/staging/stg__credit_card.sql
[2024-03-30T22:29:35.346+0000] {subprocess.py:93} INFO - [0m22:29:35
[2024-03-30T22:29:35.347+0000] {subprocess.py:93} INFO - [0m22:29:35  Done. PASS=0 WARN=0 ERROR=1 SKIP=0 TOTAL=1
[2024-03-30T22:29:37.695+0000] {subprocess.py:97} INFO - Command exited with return code 1
[2024-03-30T22:29:37.704+0000] {taskinstance.py:2728} ERROR - Task failed with exception
Traceback (most recent call last):
  File "/home/airflow/.local/lib/python3.8/site-packages/airflow/models/taskinstance.py", line 444, in _execute_task
    result = _execute_callable(context=context, **execute_callable_kwargs)
  File "/home/airflow/.local/lib/python3.8/site-packages/airflow/models/taskinstance.py", line 414, in _execute_callable
    return execute_callable(context=context, **execute_callable_kwargs)
  File "/home/airflow/.local/lib/python3.8/site-packages/airflow/operators/bash.py", line 212, in execute
    raise AirflowException(
airflow.exceptions.AirflowException: Bash command failed. The command returned a non-zero exit code 1.
[2024-03-30T22:29:37.707+0000] {taskinstance.py:1149} INFO - Marking task as UP_FOR_RETRY. dag_id=study_case_etl_all_pipeline, task_id=bash_task_2, execution_date=20240330T222905, start_date=20240330T222926, end_date=20240330T222937
[2024-03-30T22:29:37.720+0000] {standard_task_runner.py:107} ERROR - Failed to execute job 204 for task bash_task_2 (Bash command failed. The command returned a non-zero exit code 1.; 5368)
[2024-03-30T22:29:37.734+0000] {local_task_job_runner.py:234} INFO - Task exited with return code 1
[2024-03-30T22:29:37.755+0000] {taskinstance.py:3309} INFO - 0 downstream tasks scheduled from follow-on schedule check
