[2024-03-16T06:06:41.881+0000] {taskinstance.py:1979} INFO - Dependencies all met for dep_context=non-requeueable deps ti=<TaskInstance: study_case_etl_cloud_storage.local_to_gcs_task scheduled__2024-03-15T02:00:00+00:00 [queued]>
[2024-03-16T06:06:41.891+0000] {taskinstance.py:1979} INFO - Dependencies all met for dep_context=requeueable deps ti=<TaskInstance: study_case_etl_cloud_storage.local_to_gcs_task scheduled__2024-03-15T02:00:00+00:00 [queued]>
[2024-03-16T06:06:41.892+0000] {taskinstance.py:2193} INFO - Starting attempt 1 of 2
[2024-03-16T06:06:41.906+0000] {taskinstance.py:2214} INFO - Executing <Task(PythonOperator): local_to_gcs_task> on 2024-03-15 02:00:00+00:00
[2024-03-16T06:06:41.911+0000] {standard_task_runner.py:60} INFO - Started process 201 to run task
[2024-03-16T06:06:41.915+0000] {standard_task_runner.py:87} INFO - Running: ['***', 'tasks', 'run', 'study_case_etl_cloud_storage', 'local_to_gcs_task', 'scheduled__2024-03-15T02:00:00+00:00', '--job-id', '503', '--raw', '--subdir', 'DAGS_FOLDER/etl_day_bigquery/study_case_etl_cloud_storage.py', '--cfg-path', '/tmp/tmpuxnf_5si']
[2024-03-16T06:06:41.917+0000] {standard_task_runner.py:88} INFO - Job 503: Subtask local_to_gcs_task
[2024-03-16T06:06:41.978+0000] {task_command.py:423} INFO - Running <TaskInstance: study_case_etl_cloud_storage.local_to_gcs_task scheduled__2024-03-15T02:00:00+00:00 [running]> on host 72d5c878da28
[2024-03-16T06:06:42.066+0000] {taskinstance.py:2510} INFO - Exporting env vars: AIRFLOW_CTX_DAG_OWNER='Agus mahari' AIRFLOW_CTX_DAG_ID='study_case_etl_cloud_storage' AIRFLOW_CTX_TASK_ID='local_to_gcs_task' AIRFLOW_CTX_EXECUTION_DATE='2024-03-15T02:00:00+00:00' AIRFLOW_CTX_TRY_NUMBER='1' AIRFLOW_CTX_DAG_RUN_ID='scheduled__2024-03-15T02:00:00+00:00'
[2024-03-16T06:06:42.070+0000] {taskinstance.py:2728} ERROR - Task failed with exception
Traceback (most recent call last):
  File "/home/airflow/.local/lib/python3.8/site-packages/airflow/models/taskinstance.py", line 444, in _execute_task
    result = _execute_callable(context=context, **execute_callable_kwargs)
  File "/home/airflow/.local/lib/python3.8/site-packages/airflow/models/taskinstance.py", line 414, in _execute_callable
    return execute_callable(context=context, **execute_callable_kwargs)
  File "/home/airflow/.local/lib/python3.8/site-packages/airflow/operators/python.py", line 200, in execute
    return_value = self.execute_callable()
  File "/home/airflow/.local/lib/python3.8/site-packages/airflow/operators/python.py", line 217, in execute_callable
    return self.python_callable(*self.op_args, **self.op_kwargs)
  File "/opt/airflow/dags/etl_day_bigquery/study_case_etl_cloud_storage.py", line 80, in upload_to_gcs
    client = storage.Client()
  File "/home/airflow/.local/lib/python3.8/site-packages/google/cloud/storage/client.py", line 172, in __init__
    super(Client, self).__init__(
  File "/home/airflow/.local/lib/python3.8/site-packages/google/cloud/client/__init__.py", line 320, in __init__
    _ClientProjectMixin.__init__(self, project=project, credentials=credentials)
  File "/home/airflow/.local/lib/python3.8/site-packages/google/cloud/client/__init__.py", line 268, in __init__
    project = self._determine_default(project)
  File "/home/airflow/.local/lib/python3.8/site-packages/google/cloud/client/__init__.py", line 287, in _determine_default
    return _determine_default_project(project)
  File "/home/airflow/.local/lib/python3.8/site-packages/google/cloud/_helpers/__init__.py", line 152, in _determine_default_project
    _, project = google.auth.default()
  File "/home/airflow/.local/lib/python3.8/site-packages/google/auth/_default.py", line 657, in default
    credentials, project_id = checker()
  File "/home/airflow/.local/lib/python3.8/site-packages/google/auth/_default.py", line 650, in <lambda>
    lambda: _get_explicit_environ_credentials(quota_project_id=quota_project_id),
  File "/home/airflow/.local/lib/python3.8/site-packages/google/auth/_default.py", line 270, in _get_explicit_environ_credentials
    credentials, project_id = load_credentials_from_file(
  File "/home/airflow/.local/lib/python3.8/site-packages/google/auth/_default.py", line 114, in load_credentials_from_file
    raise exceptions.DefaultCredentialsError(
google.auth.exceptions.DefaultCredentialsError: File /opt/***/google_credentials.json was not found.
[2024-03-16T06:06:42.079+0000] {taskinstance.py:1149} INFO - Marking task as UP_FOR_RETRY. dag_id=study_case_etl_cloud_storage, task_id=local_to_gcs_task, execution_date=20240315T020000, start_date=20240316T060641, end_date=20240316T060642
[2024-03-16T06:06:42.089+0000] {standard_task_runner.py:107} ERROR - Failed to execute job 503 for task local_to_gcs_task (File /opt/***/google_credentials.json was not found.; 201)
[2024-03-16T06:06:42.134+0000] {local_task_job_runner.py:234} INFO - Task exited with return code 1
[2024-03-16T06:06:42.260+0000] {taskinstance.py:3309} INFO - 0 downstream tasks scheduled from follow-on schedule check
