[2024-03-03T15:41:52.812+0000] {taskinstance.py:1979} INFO - Dependencies all met for dep_context=non-requeueable deps ti=<TaskInstance: aaexample_3.load_to_mongodb_task manual__2024-03-03T15:36:17.002677+00:00 [queued]>
[2024-03-03T15:41:52.820+0000] {taskinstance.py:1979} INFO - Dependencies all met for dep_context=requeueable deps ti=<TaskInstance: aaexample_3.load_to_mongodb_task manual__2024-03-03T15:36:17.002677+00:00 [queued]>
[2024-03-03T15:41:52.820+0000] {taskinstance.py:2193} INFO - Starting attempt 2 of 2
[2024-03-03T15:41:52.832+0000] {taskinstance.py:2214} INFO - Executing <Task(PythonOperator): load_to_mongodb_task> on 2024-03-03 15:36:17.002677+00:00
[2024-03-03T15:41:52.837+0000] {standard_task_runner.py:60} INFO - Started process 3825 to run task
[2024-03-03T15:41:52.840+0000] {standard_task_runner.py:87} INFO - Running: ['***', 'tasks', 'run', 'aaexample_3', 'load_to_mongodb_task', 'manual__2024-03-03T15:36:17.002677+00:00', '--job-id', '73', '--raw', '--subdir', 'DAGS_FOLDER/other_ingestion_postgre/main_dag_sql_tiga.py', '--cfg-path', '/tmp/tmpqvyfa8xh']
[2024-03-03T15:41:52.842+0000] {standard_task_runner.py:88} INFO - Job 73: Subtask load_to_mongodb_task
[2024-03-03T15:41:52.883+0000] {task_command.py:423} INFO - Running <TaskInstance: aaexample_3.load_to_mongodb_task manual__2024-03-03T15:36:17.002677+00:00 [running]> on host 749678136a31
[2024-03-03T15:41:52.946+0000] {taskinstance.py:2510} INFO - Exporting env vars: AIRFLOW_CTX_DAG_OWNER='***' AIRFLOW_CTX_DAG_ID='aaexample_3' AIRFLOW_CTX_TASK_ID='load_to_mongodb_task' AIRFLOW_CTX_EXECUTION_DATE='2024-03-03T15:36:17.002677+00:00' AIRFLOW_CTX_TRY_NUMBER='2' AIRFLOW_CTX_DAG_RUN_ID='manual__2024-03-03T15:36:17.002677+00:00'
[2024-03-03T15:41:52.948+0000] {warnings.py:110} WARNING - /home/***/.local/lib/python3.11/site-packages/***/utils/context.py:315: AirflowContextDeprecationWarning: Accessing 'execution_date' from the template is deprecated and will be removed in a future version. Please use 'data_interval_start' or 'logical_date' instead.
  warnings.warn(_create_deprecation_warning(k, replacements))

[2024-03-03T15:41:52.962+0000] {logging_mixin.py:188} INFO - Data sebelum dimasukkan ke MongoDB:
[2024-03-03T15:41:52.963+0000] {logging_mixin.py:188} INFO - [{'1': '2', '2023-11-14 10:20:00': '2023-11-14 10:21:00', 'Transfer bank': 'Gopay', 'Sepatu Nike Air Force 1': 'Kaos Distro', 'Lunas': 'Pending', '2024-02-27 10:24:21.937107': '2024-02-27 10:24:46.362615'}, {'1': '3', '2023-11-14 10:20:00': '2023-11-14 10:22:00', 'Transfer bank': 'Gopay', 'Sepatu Nike Air Force 1': 'Pulsa Telkomsel 50GB', 'Lunas': 'Lunas', '2024-02-27 10:24:21.937107': '2024-02-27 10:24:46.362615'}, {'1': '4', '2023-11-14 10:20:00': '2023-11-14 10:23:00', 'Transfer bank': 'Gopay', 'Sepatu Nike Air Force 1': 'Top Up ShopeePay 100.000', 'Lunas': 'Pending', '2024-02-27 10:24:21.937107': '2024-02-27 10:24:46.362615'}, {'1': '5', '2023-11-14 10:20:00': '2023-11-14 10:24:00', 'Transfer bank': 'OVO', 'Sepatu Nike Air Force 1': 'Tiket Bioskop XXI', 'Lunas': 'Lunas', '2024-02-27 10:24:21.937107': '2024-02-27 10:24:46.362615'}, {'1': '6', '2023-11-14 10:20:00': '2023-11-14 10:25:00', 'Transfer bank': 'OVO', 'Sepatu Nike Air Force 1': 'Makan di Warung Padang', 'Lunas': 'Pending', '2024-02-27 10:24:21.937107': '2024-02-27 10:24:46.362615'}, {'1': '7', '2023-11-14 10:20:00': '2023-11-14 10:26:00', 'Transfer bank': 'OVO', 'Sepatu Nike Air Force 1': 'Bayar Tagihan Listrik', 'Lunas': 'Lunas', '2024-02-27 10:24:21.937107': '2024-02-27 10:24:46.362615'}, {'1': '8', '2023-11-14 10:20:00': '2023-11-14 10:27:00', 'Transfer bank': 'Dana', 'Sepatu Nike Air Force 1': 'Paket Data Indosat 1GB', 'Lunas': 'Pending', '2024-02-27 10:24:21.937107': '2024-02-27 10:24:46.362615'}, {'1': '9', '2023-11-14 10:20:00': '2023-11-14 10:28:00', 'Transfer bank': 'Dana', 'Sepatu Nike Air Force 1': 'Pesan Makanan di GrabFood', 'Lunas': 'Lunas', '2024-02-27 10:24:21.937107': '2024-02-27 10:24:46.362615'}, {'1': '10', '2023-11-14 10:20:00': '2023-11-14 10:29:00', 'Transfer bank': 'Dana', 'Sepatu Nike Air Force 1': 'Top Up GoPay 50.000', 'Lunas': 'Pending', '2024-02-27 10:24:21.937107': '2024-02-27 10:24:46.362615'}]
[2024-03-03T15:42:23.110+0000] {taskinstance.py:2728} ERROR - Task failed with exception
Traceback (most recent call last):
  File "/home/airflow/.local/lib/python3.11/site-packages/airflow/models/taskinstance.py", line 444, in _execute_task
    result = _execute_callable(context=context, **execute_callable_kwargs)
             ^^^^^^^^^^^^^^^^^^^^^^^^^^^^^^^^^^^^^^^^^^^^^^^^^^^^^^^^^^^^^
  File "/home/airflow/.local/lib/python3.11/site-packages/airflow/models/taskinstance.py", line 414, in _execute_callable
    return execute_callable(context=context, **execute_callable_kwargs)
           ^^^^^^^^^^^^^^^^^^^^^^^^^^^^^^^^^^^^^^^^^^^^^^^^^^^^^^^^^^^^
  File "/home/airflow/.local/lib/python3.11/site-packages/airflow/operators/python.py", line 200, in execute
    return_value = self.execute_callable()
                   ^^^^^^^^^^^^^^^^^^^^^^^
  File "/home/airflow/.local/lib/python3.11/site-packages/airflow/operators/python.py", line 217, in execute_callable
    return self.python_callable(*self.op_args, **self.op_kwargs)
           ^^^^^^^^^^^^^^^^^^^^^^^^^^^^^^^^^^^^^^^^^^^^^^^^^^^^^
  File "/opt/airflow/dags/other_ingestion_postgre/main_dag_sql_tiga.py", line 92, in load_to_mongodb
    collection.insert_many(data)
  File "/home/airflow/.local/lib/python3.11/site-packages/pymongo/_csot.py", line 107, in csot_wrapper
    return func(self, *args, **kwargs)
           ^^^^^^^^^^^^^^^^^^^^^^^^^^^
  File "/home/airflow/.local/lib/python3.11/site-packages/pymongo/collection.py", line 755, in insert_many
    blk.execute(write_concern, session=session)
  File "/home/airflow/.local/lib/python3.11/site-packages/pymongo/bulk.py", line 576, in execute
    return self.execute_command(generator, write_concern, session)
           ^^^^^^^^^^^^^^^^^^^^^^^^^^^^^^^^^^^^^^^^^^^^^^^^^^^^^^^
  File "/home/airflow/.local/lib/python3.11/site-packages/pymongo/bulk.py", line 443, in execute_command
    client._retryable_write(self.is_retryable, retryable_bulk, session, bulk=self)
  File "/home/airflow/.local/lib/python3.11/site-packages/pymongo/mongo_client.py", line 1522, in _retryable_write
    with self._tmp_session(session) as s:
  File "/usr/local/lib/python3.11/contextlib.py", line 137, in __enter__
    return next(self.gen)
           ^^^^^^^^^^^^^^
  File "/home/airflow/.local/lib/python3.11/site-packages/pymongo/mongo_client.py", line 1840, in _tmp_session
    s = self._ensure_session(session)
        ^^^^^^^^^^^^^^^^^^^^^^^^^^^^^
  File "/home/airflow/.local/lib/python3.11/site-packages/pymongo/mongo_client.py", line 1823, in _ensure_session
    return self.__start_session(True, causal_consistency=False)
           ^^^^^^^^^^^^^^^^^^^^^^^^^^^^^^^^^^^^^^^^^^^^^^^^^^^^
  File "/home/airflow/.local/lib/python3.11/site-packages/pymongo/mongo_client.py", line 1766, in __start_session
    self._topology._check_implicit_session_support()
  File "/home/airflow/.local/lib/python3.11/site-packages/pymongo/topology.py", line 573, in _check_implicit_session_support
    self._check_session_support()
  File "/home/airflow/.local/lib/python3.11/site-packages/pymongo/topology.py", line 589, in _check_session_support
    self._select_servers_loop(
  File "/home/airflow/.local/lib/python3.11/site-packages/pymongo/topology.py", line 259, in _select_servers_loop
    raise ServerSelectionTimeoutError(
pymongo.errors.ServerSelectionTimeoutError: ac-ojnwvdg-shard-00-01.sy84a9m.mongodb.net:27017: connection closed (configured timeouts: socketTimeoutMS: 20000.0ms, connectTimeoutMS: 20000.0ms), Timeout: 30s, Topology Description: <TopologyDescription id: 65e49a400f113581adcecc6d, topology_type: Unknown, servers: [<ServerDescription ('ac-ojnwvdg-shard-00-01.sy84a9m.mongodb.net', 27017) server_type: Unknown, rtt: None, error=AutoReconnect('ac-ojnwvdg-shard-00-01.sy84a9m.mongodb.net:27017: connection closed (configured timeouts: socketTimeoutMS: 20000.0ms, connectTimeoutMS: 20000.0ms)')>]>
[2024-03-03T15:42:23.120+0000] {taskinstance.py:1149} INFO - Marking task as FAILED. dag_id=aaexample_3, task_id=load_to_mongodb_task, execution_date=20240303T153617, start_date=20240303T154152, end_date=20240303T154223
[2024-03-03T15:42:23.134+0000] {standard_task_runner.py:107} ERROR - Failed to execute job 73 for task load_to_mongodb_task (ac-ojnwvdg-shard-00-01.sy84a9m.mongodb.net:27017: connection closed (configured timeouts: socketTimeoutMS: 20000.0ms, connectTimeoutMS: 20000.0ms), Timeout: 30s, Topology Description: <TopologyDescription id: 65e49a400f113581adcecc6d, topology_type: Unknown, servers: [<ServerDescription ('ac-ojnwvdg-shard-00-01.sy84a9m.mongodb.net', 27017) server_type: Unknown, rtt: None, error=AutoReconnect('ac-ojnwvdg-shard-00-01.sy84a9m.mongodb.net:27017: connection closed (configured timeouts: socketTimeoutMS: 20000.0ms, connectTimeoutMS: 20000.0ms)')>]>; 3825)
[2024-03-03T15:42:23.154+0000] {local_task_job_runner.py:234} INFO - Task exited with return code 1
[2024-03-03T15:42:23.166+0000] {taskinstance.py:3309} INFO - 0 downstream tasks scheduled from follow-on schedule check
