[2024-03-03T15:32:53.932+0000] {taskinstance.py:1979} INFO - Dependencies all met for dep_context=non-requeueable deps ti=<TaskInstance: aaexample_3.load_to_mongodb_task manual__2024-03-03T15:32:48.555955+00:00 [queued]>
[2024-03-03T15:32:53.940+0000] {taskinstance.py:1979} INFO - Dependencies all met for dep_context=requeueable deps ti=<TaskInstance: aaexample_3.load_to_mongodb_task manual__2024-03-03T15:32:48.555955+00:00 [queued]>
[2024-03-03T15:32:53.941+0000] {taskinstance.py:2193} INFO - Starting attempt 1 of 2
[2024-03-03T15:32:53.953+0000] {taskinstance.py:2214} INFO - Executing <Task(PythonOperator): load_to_mongodb_task> on 2024-03-03 15:32:48.555955+00:00
[2024-03-03T15:32:53.960+0000] {standard_task_runner.py:60} INFO - Started process 3700 to run task
[2024-03-03T15:32:53.963+0000] {standard_task_runner.py:87} INFO - Running: ['***', 'tasks', 'run', 'aaexample_3', 'load_to_mongodb_task', 'manual__2024-03-03T15:32:48.555955+00:00', '--job-id', '70', '--raw', '--subdir', 'DAGS_FOLDER/other_ingestion_postgre/main_dag_sql_tiga.py', '--cfg-path', '/tmp/tmpbtd2jqvg']
[2024-03-03T15:32:53.966+0000] {standard_task_runner.py:88} INFO - Job 70: Subtask load_to_mongodb_task
[2024-03-03T15:32:54.008+0000] {task_command.py:423} INFO - Running <TaskInstance: aaexample_3.load_to_mongodb_task manual__2024-03-03T15:32:48.555955+00:00 [running]> on host 749678136a31
[2024-03-03T15:32:54.073+0000] {taskinstance.py:2510} INFO - Exporting env vars: AIRFLOW_CTX_DAG_OWNER='***' AIRFLOW_CTX_DAG_ID='aaexample_3' AIRFLOW_CTX_TASK_ID='load_to_mongodb_task' AIRFLOW_CTX_EXECUTION_DATE='2024-03-03T15:32:48.555955+00:00' AIRFLOW_CTX_TRY_NUMBER='1' AIRFLOW_CTX_DAG_RUN_ID='manual__2024-03-03T15:32:48.555955+00:00'
[2024-03-03T15:32:54.075+0000] {warnings.py:110} WARNING - /home/***/.local/lib/python3.11/site-packages/***/utils/context.py:315: AirflowContextDeprecationWarning: Accessing 'execution_date' from the template is deprecated and will be removed in a future version. Please use 'data_interval_start' or 'logical_date' instead.
  warnings.warn(_create_deprecation_warning(k, replacements))

[2024-03-03T15:32:54.089+0000] {taskinstance.py:2728} ERROR - Task failed with exception
Traceback (most recent call last):
  File "/home/airflow/.local/lib/python3.11/site-packages/airflow/models/taskinstance.py", line 444, in _execute_task
    result = _execute_callable(context=context, **execute_callable_kwargs)
             ^^^^^^^^^^^^^^^^^^^^^^^^^^^^^^^^^^^^^^^^^^^^^^^^^^^^^^^^^^^^^
  File "/home/airflow/.local/lib/python3.11/site-packages/airflow/models/taskinstance.py", line 414, in _execute_callable
    return execute_callable(context=context, **execute_callable_kwargs)
           ^^^^^^^^^^^^^^^^^^^^^^^^^^^^^^^^^^^^^^^^^^^^^^^^^^^^^^^^^^^^
  File "/home/airflow/.local/lib/python3.11/site-packages/airflow/operators/python.py", line 200, in execute
    return_value = self.execute_callable()
                   ^^^^^^^^^^^^^^^^^^^^^^^
  File "/home/airflow/.local/lib/python3.11/site-packages/airflow/operators/python.py", line 217, in execute_callable
    return self.python_callable(*self.op_args, **self.op_kwargs)
           ^^^^^^^^^^^^^^^^^^^^^^^^^^^^^^^^^^^^^^^^^^^^^^^^^^^^^
  File "/opt/airflow/dags/other_ingestion_postgre/main_dag_sql_tiga.py", line 75, in load_to_mongodb
    client = pymongo.MongoClient("mongodb://127.0.0.1:27017/?direcConnection=true&serverSelectionTimeoutMS:2000")
             ^^^^^^^^^^^^^^^^^^^^^^^^^^^^^^^^^^^^^^^^^^^^^^^^^^^^^^^^^^^^^^^^^^^^^^^^^^^^^^^^^^^^^^^^^^^^^^^^^^^^
  File "/home/airflow/.local/lib/python3.11/site-packages/pymongo/mongo_client.py", line 771, in __init__
    res = uri_parser.parse_uri(
          ^^^^^^^^^^^^^^^^^^^^^
  File "/home/airflow/.local/lib/python3.11/site-packages/pymongo/uri_parser.py", line 529, in parse_uri
    options.update(split_options(opts, validate, warn, normalize))
                   ^^^^^^^^^^^^^^^^^^^^^^^^^^^^^^^^^^^^^^^^^^^^^^
  File "/home/airflow/.local/lib/python3.11/site-packages/pymongo/uri_parser.py", line 353, in split_options
    raise InvalidURI("MongoDB URI options are key=value pairs.") from None
pymongo.errors.InvalidURI: MongoDB URI options are key=value pairs.
[2024-03-03T15:32:54.097+0000] {taskinstance.py:1149} INFO - Marking task as UP_FOR_RETRY. dag_id=aaexample_3, task_id=load_to_mongodb_task, execution_date=20240303T153248, start_date=20240303T153253, end_date=20240303T153254
[2024-03-03T15:32:54.110+0000] {standard_task_runner.py:107} ERROR - Failed to execute job 70 for task load_to_mongodb_task (MongoDB URI options are key=value pairs.; 3700)
[2024-03-03T15:32:54.135+0000] {local_task_job_runner.py:234} INFO - Task exited with return code 1
[2024-03-03T15:32:54.152+0000] {taskinstance.py:3309} INFO - 0 downstream tasks scheduled from follow-on schedule check
