[2024-03-16T06:18:15.233+0000] {taskinstance.py:1979} INFO - Dependencies all met for dep_context=non-requeueable deps ti=<TaskInstance: study_case_etl_cloud_storage.local_to_gcs_task scheduled__2024-03-15T19:00:00+00:00 [queued]>
[2024-03-16T06:18:15.251+0000] {taskinstance.py:1979} INFO - Dependencies all met for dep_context=requeueable deps ti=<TaskInstance: study_case_etl_cloud_storage.local_to_gcs_task scheduled__2024-03-15T19:00:00+00:00 [queued]>
[2024-03-16T06:18:15.254+0000] {taskinstance.py:2193} INFO - Starting attempt 2 of 2
[2024-03-16T06:18:15.915+0000] {taskinstance.py:2214} INFO - Executing <Task(PythonOperator): local_to_gcs_task> on 2024-03-15 19:00:00+00:00
[2024-03-16T06:18:15.943+0000] {standard_task_runner.py:60} INFO - Started process 99 to run task
[2024-03-16T06:18:15.960+0000] {standard_task_runner.py:87} INFO - Running: ['***', 'tasks', 'run', 'study_case_etl_cloud_storage', 'local_to_gcs_task', 'scheduled__2024-03-15T19:00:00+00:00', '--job-id', '589', '--raw', '--subdir', 'DAGS_FOLDER/etl_day_bigquery/study_case_etl_cloud_storage.py', '--cfg-path', '/tmp/tmpykq3_fe4']
[2024-03-16T06:18:15.985+0000] {standard_task_runner.py:88} INFO - Job 589: Subtask local_to_gcs_task
[2024-03-16T06:18:16.354+0000] {task_command.py:423} INFO - Running <TaskInstance: study_case_etl_cloud_storage.local_to_gcs_task scheduled__2024-03-15T19:00:00+00:00 [running]> on host 5aeb2644b29c
[2024-03-16T06:18:17.145+0000] {taskinstance.py:2510} INFO - Exporting env vars: AIRFLOW_CTX_DAG_OWNER='Agus mahari' AIRFLOW_CTX_DAG_ID='study_case_etl_cloud_storage' AIRFLOW_CTX_TASK_ID='local_to_gcs_task' AIRFLOW_CTX_EXECUTION_DATE='2024-03-15T19:00:00+00:00' AIRFLOW_CTX_TRY_NUMBER='2' AIRFLOW_CTX_DAG_RUN_ID='scheduled__2024-03-15T19:00:00+00:00'
[2024-03-16T06:18:17.517+0000] {taskinstance.py:2728} ERROR - Task failed with exception
Traceback (most recent call last):
  File "/home/airflow/.local/lib/python3.8/site-packages/airflow/models/taskinstance.py", line 444, in _execute_task
    result = _execute_callable(context=context, **execute_callable_kwargs)
  File "/home/airflow/.local/lib/python3.8/site-packages/airflow/models/taskinstance.py", line 414, in _execute_callable
    return execute_callable(context=context, **execute_callable_kwargs)
  File "/home/airflow/.local/lib/python3.8/site-packages/airflow/operators/python.py", line 200, in execute
    return_value = self.execute_callable()
  File "/home/airflow/.local/lib/python3.8/site-packages/airflow/operators/python.py", line 217, in execute_callable
    return self.python_callable(*self.op_args, **self.op_kwargs)
  File "/opt/airflow/dags/etl_day_bigquery/study_case_etl_cloud_storage.py", line 84, in upload_to_gcs
    blob.upload_from_filename(local_file)
  File "/home/airflow/.local/lib/python3.8/site-packages/google/cloud/storage/blob.py", line 2929, in upload_from_filename
    self._handle_filename_and_upload(
  File "/home/airflow/.local/lib/python3.8/site-packages/google/cloud/storage/blob.py", line 2797, in _handle_filename_and_upload
    with open(filename, "rb") as file_obj:
FileNotFoundError: [Errno 2] No such file or directory: '/opt/airflow/data/aplikasi_table_2024-03-15-19-00-00.parquet'
[2024-03-16T06:18:17.608+0000] {taskinstance.py:1149} INFO - Marking task as FAILED. dag_id=study_case_etl_cloud_storage, task_id=local_to_gcs_task, execution_date=20240315T190000, start_date=20240316T061815, end_date=20240316T061817
[2024-03-16T06:18:17.765+0000] {standard_task_runner.py:107} ERROR - Failed to execute job 589 for task local_to_gcs_task ([Errno 2] No such file or directory: '/opt/airflow/data/aplikasi_table_2024-03-15-19-00-00.parquet'; 99)
[2024-03-16T06:18:17.839+0000] {local_task_job_runner.py:234} INFO - Task exited with return code 1
[2024-03-16T06:18:17.874+0000] {taskinstance.py:3309} INFO - 0 downstream tasks scheduled from follow-on schedule check
