[2024-03-03T20:07:05.467+0000] {taskinstance.py:1979} INFO - Dependencies all met for dep_context=non-requeueable deps ti=<TaskInstance: aaexample_4.fetch_data_task manual__2024-03-03T20:07:03.791136+00:00 [queued]>
[2024-03-03T20:07:05.477+0000] {taskinstance.py:1979} INFO - Dependencies all met for dep_context=requeueable deps ti=<TaskInstance: aaexample_4.fetch_data_task manual__2024-03-03T20:07:03.791136+00:00 [queued]>
[2024-03-03T20:07:05.477+0000] {taskinstance.py:2193} INFO - Starting attempt 1 of 2
[2024-03-03T20:07:05.491+0000] {taskinstance.py:2214} INFO - Executing <Task(PythonOperator): fetch_data_task> on 2024-03-03 20:07:03.791136+00:00
[2024-03-03T20:07:05.498+0000] {standard_task_runner.py:60} INFO - Started process 7401 to run task
[2024-03-03T20:07:05.500+0000] {standard_task_runner.py:87} INFO - Running: ['***', 'tasks', 'run', 'aaexample_4', 'fetch_data_task', 'manual__2024-03-03T20:07:03.791136+00:00', '--job-id', '88', '--raw', '--subdir', 'DAGS_FOLDER/other_ingestion_postgre/main_dag_sql_empat.py', '--cfg-path', '/tmp/tmp2c2icrlk']
[2024-03-03T20:07:05.503+0000] {standard_task_runner.py:88} INFO - Job 88: Subtask fetch_data_task
[2024-03-03T20:07:05.545+0000] {task_command.py:423} INFO - Running <TaskInstance: aaexample_4.fetch_data_task manual__2024-03-03T20:07:03.791136+00:00 [running]> on host 749678136a31
[2024-03-03T20:07:05.607+0000] {taskinstance.py:2510} INFO - Exporting env vars: AIRFLOW_CTX_DAG_OWNER='***' AIRFLOW_CTX_DAG_ID='aaexample_4' AIRFLOW_CTX_TASK_ID='fetch_data_task' AIRFLOW_CTX_EXECUTION_DATE='2024-03-03T20:07:03.791136+00:00' AIRFLOW_CTX_TRY_NUMBER='1' AIRFLOW_CTX_DAG_RUN_ID='manual__2024-03-03T20:07:03.791136+00:00'
[2024-03-03T20:07:05.609+0000] {warnings.py:110} WARNING - /home/***/.local/lib/python3.11/site-packages/***/utils/context.py:315: AirflowContextDeprecationWarning: Accessing 'execution_date' from the template is deprecated and will be removed in a future version. Please use 'data_interval_start' or 'logical_date' instead.
  warnings.warn(_create_deprecation_warning(k, replacements))

[2024-03-03T20:07:05.620+0000] {taskinstance.py:2728} ERROR - Task failed with exception
Traceback (most recent call last):
  File "/home/airflow/.local/lib/python3.11/site-packages/airflow/models/taskinstance.py", line 444, in _execute_task
    result = _execute_callable(context=context, **execute_callable_kwargs)
             ^^^^^^^^^^^^^^^^^^^^^^^^^^^^^^^^^^^^^^^^^^^^^^^^^^^^^^^^^^^^^
  File "/home/airflow/.local/lib/python3.11/site-packages/airflow/models/taskinstance.py", line 414, in _execute_callable
    return execute_callable(context=context, **execute_callable_kwargs)
           ^^^^^^^^^^^^^^^^^^^^^^^^^^^^^^^^^^^^^^^^^^^^^^^^^^^^^^^^^^^^
  File "/home/airflow/.local/lib/python3.11/site-packages/airflow/operators/python.py", line 200, in execute
    return_value = self.execute_callable()
                   ^^^^^^^^^^^^^^^^^^^^^^^
  File "/home/airflow/.local/lib/python3.11/site-packages/airflow/operators/python.py", line 217, in execute_callable
    return self.python_callable(*self.op_args, **self.op_kwargs)
           ^^^^^^^^^^^^^^^^^^^^^^^^^^^^^^^^^^^^^^^^^^^^^^^^^^^^^
  File "/opt/airflow/dags/other_ingestion_postgre/main_dag_sql_empat.py", line 39, in fetch_data
    conn = get_mysql_connection()
           ^^^^^^^^^^^^^^^^^^^^^^
  File "/opt/airflow/dags/utils/mysqlconnection.py", line 17, in get_mysql_connection
    engine = create_engine(database_url, echo=True)
             ^^^^^^^^^^^^^^^^^^^^^^^^^^^^^^^^^^^^^^
  File "<string>", line 2, in create_engine
  File "/home/airflow/.local/lib/python3.11/site-packages/sqlalchemy/util/deprecations.py", line 375, in warned
    return fn(*args, **kwargs)
           ^^^^^^^^^^^^^^^^^^^
  File "/home/airflow/.local/lib/python3.11/site-packages/sqlalchemy/engine/create.py", line 544, in create_engine
    dbapi = dialect_cls.dbapi(**dbapi_args)
            ^^^^^^^^^^^^^^^^^^^^^^^^^^^^^^^
  File "/home/airflow/.local/lib/python3.11/site-packages/sqlalchemy/dialects/mysql/pymysql.py", line 80, in dbapi
    return __import__("pymysql")
           ^^^^^^^^^^^^^^^^^^^^^
ModuleNotFoundError: No module named 'pymysql'
[2024-03-03T20:07:05.629+0000] {taskinstance.py:1149} INFO - Marking task as UP_FOR_RETRY. dag_id=aaexample_4, task_id=fetch_data_task, execution_date=20240303T200703, start_date=20240303T200705, end_date=20240303T200705
[2024-03-03T20:07:05.639+0000] {standard_task_runner.py:107} ERROR - Failed to execute job 88 for task fetch_data_task (No module named 'pymysql'; 7401)
[2024-03-03T20:07:05.673+0000] {local_task_job_runner.py:234} INFO - Task exited with return code 1
[2024-03-03T20:07:05.694+0000] {taskinstance.py:3309} INFO - 0 downstream tasks scheduled from follow-on schedule check
